Workbook

Sheet Summary
A1: Bonbird keyword research
A2: UAE · Pakistan · Oman · Qatar · researched 9 Oct 2026. Counts and volumes below are live formulas over the Keywords tab.
A4: Market | B4: Keywords targeted | C4: P1 keywords | D4: P1 searches / mo | E4: All targeted searches / mo | F4: Via Business Profile (searches / mo)
A5: UAE | B5: =COUNTIFS(Keywords!$A:$A,$A5) | C5: =COUNTIFS(Keywords!$A:$A,$A5,Keywords!$K:$K,"P1") | D5: =SUMIFS(Keywords!$C:$C,Keywords!$A:$A,$A5,Keywords!$K:$K,"P1") | E5: =SUMIFS(Keywords!$C:$C,Keywords!$A:$A,$A5) | F5: =SUMIFS(Keywords!$C:$C,Keywords!$A:$A,$A5,Keywords!$J:$J,"Business Profile*")
A6: Pakistan | B6: =COUNTIFS(Keywords!$A:$A,$A6) | C6: =COUNTIFS(Keywords!$A:$A,$A6,Keywords!$K:$K,"P1") | D6: =SUMIFS(Keywords!$C:$C,Keywords!$A:$A,$A6,Keywords!$K:$K,"P1") | E6: =SUMIFS(Keywords!$C:$C,Keywords!$A:$A,$A6) | F6: =SUMIFS(Keywords!$C:$C,Keywords!$A:$A,$A6,Keywords!$J:$J,"Business Profile*")
A7: Oman | B7: =COUNTIFS(Keywords!$A:$A,$A7) | C7: =COUNTIFS(Keywords!$A:$A,$A7,Keywords!$K:$K,"P1") | D7: =SUMIFS(Keywords!$C:$C,Keywords!$A:$A,$A7,Keywords!$K:$K,"P1") | E7: =SUMIFS(Keywords!$C:$C,Keywords!$A:$A,$A7) | F7: =SUMIFS(Keywords!$C:$C,Keywords!$A:$A,$A7,Keywords!$J:$J,"Business Profile*")
A8: Qatar | B8: =COUNTIFS(Keywords!$A:$A,$A8) | C8: =COUNTIFS(Keywords!$A:$A,$A8,Keywords!$K:$K,"P1") | D8: =SUMIFS(Keywords!$C:$C,Keywords!$A:$A,$A8,Keywords!$K:$K,"P1") | E8: =SUMIFS(Keywords!$C:$C,Keywords!$A:$A,$A8) | F8: =SUMIFS(Keywords!$C:$C,Keywords!$A:$A,$A8,Keywords!$J:$J,"Business Profile*")
A9: Total | B9: =SUM(B5:B8) | C9: =SUM(C5:C8) | D9: =SUM(D5:D8) | E9: =SUM(E5:E8) | F9: =SUM(F5:F8)
A11: What the research says
A12: 1. Across all four markets, the Maps pack appears above the results for every search checked. Google Business Profile is the #1 lever everywhere, including the big generic terms.
A13: 2. The biggest generic terms are not winnable with a page: 'fried chicken', 'chicken burger', 'tenders', 'strips', 'wings', 'sandwich', 'wrap' show recipes; 'crispy chicken' (UAE) and 'hot chicken' (Qatar, Oman) are rival brand names.
A14: 3. UAE: Bonbird is already the top restaurant website for most generic local searches (#2–#5). The constraint is that this demand is small and its clicks go to the Maps pack and aggregators. Levers: Business Profile, list/aggregator inclusion, titles. Open goal: Nashville hot chicken (no restaurant has a real page).
A15: 4. Pakistan: the volume is 'restaurants in [area]' — Johar Town 14,800, Gulberg 12,100 (+5,400), DHA 9,900 — where Bonbird has venues. Page one is lists (TripAdvisor, foodpanda, local blogs), so the win is list inclusion + Business Profiles, plus specific venue-page terms. Kababjees leads nationally via brand + deal pages.
A16: 5. Oman and Qatar: competitors mostly have no websites. Bonbird already ranks #1 (Muscat) and #2 (Doha) for fried chicken searches. Biggest winnable term: 'west walk restaurants' (2,400, weak page one). Raising Cane's owns the Qatar Maps pack.
A17: 6. Partner-owned Business Profiles (Pakistan, Oman, Qatar) block the #1 lever in three markets until Yolk gets manager access.

Sheet Keywords
A1: Market | B1: Keyword | C1: Searches / mo | D1: Volume source | E1: Cluster | F1: What Google shows (page one) | G1: Bonbird now | H1: Who ranks / competition | I1: Target page or asset | J1: Lever | K1: Priority | L1: Notes
A2: UAE | B2: chicken near me | C2: 8100 | D2: Google Ads (DataForSEO), monthly | E2: Near me | F2: Maps pack + restaurant listings | G2: #2 (snapshot) · GSC avg #6.0 | H2: Talabat #1, Crispy Chicken #2, Zomato #3, Texas #5 | I2: 5 UAE Business Profiles (+ /ae/dubai/) | J2: Business Profile | K2: P1 | L2: Bonbird already top organic restaurant site
A3: UAE | B3: fried chicken near me | C3: 4400 | D3: Google Ads (DataForSEO), monthly | E3: Near me | F3: Maps pack + AI Overview + lists (Zomato, magicpin, Restaurant Guru, MyDubaiBest) | G3: #3 (snapshot) · GSC avg #7.6 | H3: Zomato, magicpin, Restaurant Guru, MyDubaiBest, Top-Rated | I3: 5 UAE Business Profiles | J3: Business Profile + list outreach | K3: P1 | L3: Get Bonbird onto the ranking lists
A4: UAE | B4: crispy chicken near me | C4: 4400 | D4: Google Ads (DataForSEO), monthly | E4: Near me | F4: Maps pack (not page-checked) | G4: GSC avg #7.8 | H4: — | I4: 5 UAE Business Profiles | J4: Business Profile | K4: P1
A5: UAE | B5: best chicken near me | C5: 720 | D5: Google Ads (DataForSEO), monthly | E5: Near me | F5: Maps pack | G5: #3 (snapshot) | H5: — | I5: 5 UAE Business Profiles | J5: Business Profile | K5: P2
A6: UAE | B6: good chicken near me | C6: 720 | D6: Google Ads (DataForSEO), monthly | E6: Near me | F6: Maps pack | G6: #6 (snapshot) | H6: — | I6: 5 UAE Business Profiles | J6: Business Profile | K6: P2
A7: UAE | B7: chicken shop near me | C7: 880 | D7: Google Ads (DataForSEO), monthly | E7: Near me | F7: Maps pack | G7: GSC avg #7.7 | H7: — | I7: 5 UAE Business Profiles | J7: Business Profile | K7: P2
A8: UAE | B8: chicken restaurant near me | C8: 480 | D8: Google Ads (DataForSEO), monthly | E8: Near me | F8: Maps pack | G8: #3 (snapshot) · GSC #5.7 | H8: — | I8: 5 UAE Business Profiles | J8: Business Profile | K8: P2
A9: UAE | B9: chicken burger near me | C9: 260 | D9: Google Ads (DataForSEO), monthly | E9: Near me | F9: Maps pack | G9: #3 (snapshot) | H9: Jollibee #6 | I9: 5 UAE Business Profiles | J9: Business Profile | K9: P2
A10: UAE | B10: chicken tenders near me | C10: 170 | D10: Google Ads (DataForSEO), monthly | E10: Near me | F10: Maps pack | G10: #12 (snapshot) | H10: Texas #3–8 | I10: 5 UAE Business Profiles + /ae/chicken-tenders/ | J10: Business Profile + page | K10: P2
A11: UAE | B11: spicy chicken near me | C11: 210 | D11: Google Ads (DataForSEO), monthly | E11: Near me | F11: Talabat/Zomato listings + Time Out Dubai '13 best places to order fried chicken' | G11: not ranking | H11: Spicy Fresh Chicken (rival), Time Out list | I11: Business Profile + Time Out list | J11: List outreach | K11: P2 | L11: Time Out Dubai list is an outreach target
A12: UAE | B12: hot chicken near me | C12: 110 | D12: Google Ads (DataForSEO), monthly | E12: Near me | F12: Maps pack | G12: not ranking | H12: — | I12: 5 UAE Business Profiles | J12: Business Profile | K12: P3
A13: UAE | B13: burger near me | C13: 27100 | D13: Google Ads (DataForSEO), monthly | E13: Near me (burger) | F13: Maps pack (not page-checked) | G13: GSC avg #8.1 | H13: Burger chains | I13: 5 UAE Business Profiles (secondary category) | J13: Business Profile | K13: P3 | L13: Bonbird is a chicken brand; burger is secondary
A14: UAE | B14: fast food near me | C14: 12100 | D14: Google Ads (DataForSEO), monthly | E14: Near me (fast food) | F14: Maps pack (not page-checked) | G14: GSC avg #12.4 | H14: Chains | I14: 5 UAE Business Profiles | J14: Business Profile | K14: P3
A15: UAE | B15: best fried chicken in dubai | C15: 590 | D15: Google Ads (DataForSEO), monthly | E15: Dubai | F15: AI Overview + lists (Zomato, TikTok, TripAdvisor, Medium) | G15: #2 (snapshot) · GSC avg #5.6 | H15: Zomato #1, TikTok #2, Dave's #24 | I15: /ae/dubai/ | J15: Page (title) + list outreach | K15: P1 | L15: Bonbird #3 on live check
A16: UAE | B16: best fried chicken dubai | C16: 590 | D16: Google Ads (DataForSEO), monthly | E16: Dubai | F16: Same cluster as above | G16: #2 (snapshot) · GSC avg #6.1 | H16: — | I16: /ae/dubai/ | J16: Page (title) | K16: P1 | L16: Same keyword cluster
A17: UAE | B17: fried chicken dubai | C17: 390 | D17: Google Ads (DataForSEO), monthly | E17: Dubai | F17: Restaurants | G17: #2 (snapshot) · GSC avg #9.4 | H17: Texas #12 | I17: /ae/dubai/ | J17: Page (title) | K17: P1
A18: UAE | B18: crispy chicken dubai | C18: 1900 | D18: Google Ads (DataForSEO), monthly | E18: Dubai | F18: Not page-checked; may include rival brand 'Crispy Chicken UAE' | G18: #7 (snapshot) · GSC avg #9.6 | H18: Crispy Chicken UAE (brand) | I18: /ae/dubai/ | J18: Page | K18: P2 | L18: Check page one before relying on it
A19: UAE | B19: chicken dubai / chicken in dubai | C19: 480 | D19: Google Ads (DataForSEO), monthly | E19: Dubai | F19: Restaurants | G19: #4 (snapshot) | H19: Texas #13, Dave's #10 | I19: /ae/dubai/ | J19: Page | K19: P2
A20: UAE | B20: chicken restaurants in dubai (+ variants) | C20: 170 | D20: Google Ads (DataForSEO), monthly | E20: Dubai | F20: Restaurants | G20: #8–11 (snapshot) | H20: Texas #1–4 | I20: /ae/dubai/ | J20: Page | K20: P2 | L20: Texas Chicken is the site to beat
A21: UAE | B21: best chicken abu dhabi | C21: 1300 | D21: Google Ads (DataForSEO), monthly | E21: Abu Dhabi | F21: Restaurants (not page-checked) | G21: #6 (snapshot) · GSC avg #8.9 | H21: — | I21: /ae/abu-dhabi/ | J21: Page | K21: P1
A22: UAE | B22: crispy chicken abu dhabi | C22: 2400 | D22: Google Ads (DataForSEO), monthly | E22: Abu Dhabi | F22: Not page-checked; may include rival brand | G22: GSC avg #9.6 | H22: Crispy Chicken UAE has Abu Dhabi branches | I22: /ae/abu-dhabi/ | J22: Page | K22: P2 | L22: Check page one before relying on it
A23: UAE | B23: chicken abu dhabi | C23: 260 | D23: Google Ads (DataForSEO), monthly | E23: Abu Dhabi | F23: Restaurants | G23: #2 (snapshot) | H23: — | I23: /ae/abu-dhabi/ | J23: Page | K23: P2
A24: UAE | B24: best fried chicken abu dhabi | C24: 110 | D24: Google Ads (DataForSEO), monthly | E24: Abu Dhabi | F24: Restaurants | G24: GSC avg #5.7 | H24: — | I24: /ae/abu-dhabi/ | J24: Page | K24: P2
A25: UAE | B25: fried chicken abu dhabi | C25: 140 | D25: Google Ads (DataForSEO), monthly | E25: Abu Dhabi | F25: Restaurants | G25: GSC avg #16.5 | H25: — | I25: /ae/abu-dhabi/ | J25: Page | K25: P2
A26: UAE | B26: chicken sharjah | C26: 320 | D26: Google Ads (DataForSEO), monthly | E26: Sharjah | F26: Restaurants | G26: #8 (snapshot) | H26: — | I26: /ae/sharjah/ | J26: Page | K26: P2
A27: UAE | B27: fried chicken sharjah | C27: 140 | D27: Google Ads (DataForSEO), monthly | E27: Sharjah | F27: Restaurants | G27: GSC avg #5.1 | H27: — | I27: /ae/sharjah/ | J27: Page | K27: P3
A28: UAE | B28: best chicken | C28: 1600 | D28: Google Ads (DataForSEO), monthly | E28: Generic | F28: Not page-checked | G28: #9 (snapshot) · GSC avg #8.5 | H28: — | I28: ONE page: today /ae/abu-dhabi/ and a journal post compete | J28: Page (merge overlap) | K28: P2 | L28: Cannibalisation to fix
A29: UAE | B29: hot fried chicken | C29: 1000 | D29: Google Ads (DataForSEO), monthly | E29: Hot chicken | F29: Restaurants | G29: #5 (snapshot) | H29: Dave's #7 | I29: /ae/chicken/ (Nashville hot chicken page) | J29: Page | K29: P1
A30: UAE | B30: nashville chicken | C30: 480 | D30: Google Ads (DataForSEO), monthly | E30: Hot chicken | F30: Aggregator listings only (Zomato, Last Exit, Talabat) + TikTok | G30: not ranking | H30: Nash Hot Chicken, Dave's (via listings) | I30: /ae/chicken/ (Nashville hot chicken page) | J30: Page + delivery listings | K30: P1 | L30: No restaurant has a real page — open goal
A31: UAE | B31: hot chicken | C31: 320 | D31: Google Ads (DataForSEO), monthly | E31: Hot chicken | F31: Dave's listings (MenuPages, Zomato, TripAdvisor) + What's On | G31: not ranking | H31: Dave's (via listings) | I31: /ae/chicken/ (Nashville hot chicken page) | J31: Page + delivery listings | K31: P1
A32: UAE | B32: nashville hot chicken | C32: 260 | D32: Google Ads (DataForSEO), monthly | E32: Hot chicken | F32: Talabat #1, Wikipedia, Noon, Deliveroo | G32: not ranking | H32: Nashville Spicy Hot Chicken (via Talabat) | I32: /ae/chicken/ (Nashville hot chicken page) | J32: Page + delivery listings | K32: P1
A33: UAE | B33: nashville hot chicken dubai / nashville chicken dubai | C33: 140 | D33: Google Ads (DataForSEO), monthly | E33: Hot chicken | F33: Not page-checked | G33: not ranking | H33: — | I33: /ae/chicken/ | J33: Page | K33: P2
A34: UAE | B34: fried chicken restaurant | C34: 260 | D34: Google Ads (DataForSEO), monthly | E34: Generic | F34: Restaurants | G34: #4 (snapshot) | H34: — | I34: /ae/chicken/ | J34: Page | K34: P2
A35: UAE | B35: best fried chicken restaurant(s) | C35: 140 | D35: Google Ads (DataForSEO), monthly | E35: Generic | F35: Restaurants | G35: #4 (snapshot) | H35: — | I35: /ae/dubai/ | J35: Page | K35: P3
A36: UAE | B36: mirdif city center restaurants (+ variants) | C36: 5400 | D36: Google Ads (DataForSEO), monthly | E36: Mall | F36: Not page-checked | G36: GSC avg #50 (homepage ranks, not the venue page) | H36: Mall directory, TripAdvisor (likely) | I36: /ae/dubai/mirdif/ | J36: Page + mall directory link | K36: P1 | L36: Largest single UAE opportunity; check page one
A37: UAE | B37: mirdif city center food court | C37: 480 | D37: Google Ads (DataForSEO), monthly | E37: Mall | F37: Not page-checked | G37: GSC avg #26 | H37: — | I37: /ae/dubai/mirdif/ | J37: Page | K37: P2
A38: UAE | B38: city walk restaurants | C38: 253 | D38: Search Console impressions, 90 days (no Ads volume) | E38: Mall | F38: Not page-checked | G38: GSC avg #37 (homepage ranks) | H38: — | I38: /ae/dubai/city-walk/ | J38: Page + mall directory link | K38: P2
A39: UAE | B39: fried chicken | C39: 5400 | D39: Google Ads (DataForSEO), monthly | E39: Generic head term | F39: Recipes (YouTube, food blogs) + Maps pack on top | G39: GSC avg #10.9 | H39: Recipe sites | I39: 5 UAE Business Profiles | J39: Business Profile only | K39: P1 | L39: Restaurant demand is in the Maps pack, not organic
A40: UAE | B40: chicken burger | C40: 1900 | D40: Google Ads (DataForSEO), monthly | E40: Generic head term | F40: Recipes; Bonbird journal #7 | G40: Bonbird journal #7 | H40: Recipe sites | I40: Business Profiles | J40: Business Profile only | K40: P3
...

Sheet Page map
A1: Page or asset | B1: Market | C1: Primary keyword cluster | D1: Supporting keywords | E1: Searches / mo (sum) | F1: Status / action
A2: /ae/chicken/ | B2: UAE | C2: Nashville hot chicken | D2: nashville chicken, hot chicken, nashville hot chicken, hot fried chicken, fried chicken restaurant | E2: =SUMIFS(Keywords!$C:$C,Keywords!$I:$I,"/ae/chicken/*") | F2: Retitle to Nashville hot chicken (remove false 'broasted'); website chat adds flavours section (6 heat levels)
A3: /ae/dubai/ | B3: UAE | C3: best fried chicken in dubai | D3: fried chicken dubai, crispy chicken dubai, chicken (in) dubai, chicken restaurants in dubai | E3: =SUMIFS(Keywords!$C:$C,Keywords!$I:$I,"/ae/dubai/") | F3: Retitle; already #2–#5
A4: /ae/abu-dhabi/ | B4: UAE | C4: best chicken abu dhabi | D4: crispy chicken abu dhabi, chicken abu dhabi, fried chicken abu dhabi | E4: =SUMIFS(Keywords!$C:$C,Keywords!$I:$I,"/ae/abu-dhabi/") | F4: Title changed 23 Sep — wait for mid-Oct grade
A5: /ae/sharjah/ | B5: UAE | C5: chicken sharjah | D5: fried chicken sharjah | E5: =SUMIFS(Keywords!$C:$C,Keywords!$I:$I,"/ae/sharjah/") | F5: Minor
A6: /ae/dubai/mirdif/ | B6: UAE | C6: mirdif city center restaurants | D6: mirdif city center food court | E6: =SUMIFS(Keywords!$C:$C,Keywords!$I:$I,"/ae/dubai/mirdif/") | F6: Retitle with 'Mirdif City Centre' + mall-dining content + mall directory link
A7: /ae/dubai/city-walk/ | B7: UAE | C7: city walk restaurants | E7: =SUMIFS(Keywords!$C:$C,Keywords!$I:$I,"/ae/dubai/city-walk/*") | F7: Mall directory link
A8: 5 UAE Business Profiles | B8: UAE | C8: near me (all variants) + generic head terms | D8: chicken near me, fried chicken near me, crispy chicken near me, fried chicken… | E8: =SUMIFS(Keywords!$C:$C,Keywords!$A:$A,"UAE",Keywords!$J:$J,"Business Profile*") | F8: Fix website links to venue pages; categories; weekly posts; reviews
A9: /pk/lahore/cue-cinemas/ (Gulberg) | B9: Pakistan | C9: fast food in gulberg | D9: gulberg restaurants (via lists + Maps) | E9: =SUMIFS(Keywords!$C:$C,Keywords!$I:$I,"Gulberg*")+SUMIFS(Keywords!$C:$C,Keywords!$I:$I,"/pk/lahore/cue-cinemas/") | F9: Retitle leading with Gulberg; list outreach; partner profile access
A10: /pk/lahore/dolmen-mall/ (DHA) | B10: Pakistan | C10: dolmen mall restaurants | D10: restaurants in dha lahore, dha restaurants (via lists + Maps) | E10: =SUMIFS(Keywords!$C:$C,Keywords!$I:$I,"Dolmen*")+SUMIFS(Keywords!$C:$C,Keywords!$I:$I,"/pk/lahore/dolmen-mall/*") | F10: Retitle with Dolmen Mall + DHA
A11: /pk/lahore/johar-town/ | B11: Pakistan | C11: johar town restaurants (via lists + Maps) | E11: =SUMIFS(Keywords!$C:$C,Keywords!$I:$I,"Johar*") | F11: List outreach + partner profile access
A12: /pk/lahore/ | B12: Pakistan | C12: fried chicken lahore | D12: best fried chicken in lahore, fast food lahore | E12: =SUMIFS(Keywords!$C:$C,Keywords!$I:$I,"/pk/lahore/") | F12: Retitle
A13: /om/muscat/ | B13: Oman | C13: fried chicken muscat | D13: best fried chicken in muscat | E13: =SUMIFS(Keywords!$C:$C,Keywords!$I:$I,"/om/muscat/") | F13: Already #1 live; split overlap with Souq Al Madina page
A14: /om/seeb/ | B14: Oman | C14: restaurants in seeb | E14: =SUMIFS(Keywords!$C:$C,Keywords!$I:$I,"/om/seeb/*") | F14: Retitle
A15: /qa/doha/west-walk/ | B15: Qatar | C15: west walk restaurants | D15: west walk doha | E15: =SUMIFS(Keywords!$C:$C,Keywords!$I:$I,"/qa/doha/west-walk/*") | F15: Winnable — strengthen page + profile
A16: /qa/doha/ | B16: Qatar | C16: best fried chicken in qatar | D16: fried chicken doha | E16: =SUMIFS(Keywords!$C:$C,Keywords!$I:$I,"/qa/doha/") | F16: Already #2–#6 live
A17: /qa/ | B17: Qatar | C17: fried chicken qatar | E17: =SUMIFS(Keywords!$C:$C,Keywords!$I:$I,"/qa/") | F17: Retitle

Sheet Competitors
A1: Market | B1: Competitor | C1: Website | D1: Keywords it ranks for (market) | E1: What it ranks with | F1: Ranking website?
A2: UAE | B2: KFC | C2: uae.kfc.me | D2: 627 | E2: Store pages for malls/food courts and 'drive thru near me'; brand searches | F2: Yes
A3: UAE | B3: Texas Chicken | C3: uae.texaschicken.com | D3: 114 | E3: 'chicken restaurant(s) in dubai' #1–4, 'chicken strips/tenders near me' #2–3 — the website to beat | F3: Yes
A4: UAE | B4: Jollibee | C4: jollibeeuae.com | D4: 86 | E4: Mostly brand + Filipino dishes | F4: Yes
A5: UAE | B5: Popeyes | C5: popeyesuae.com | D5: 73 | E5: Mostly brand | F5: Yes
A6: UAE | B6: Raising Cane's | C6: raisingcanes.com (global) | D6: 74 | E6: No UAE site; ranks via Zomato/Deliveroo/Alshaya | F6: Global only
A7: UAE | B7: Dave's Hot Chicken | C7: daveshotchicken.com (global) | D7: 45 | E7: UAE presence via listings (MenuPages, Zomato, TripAdvisor) — owns 'hot chicken' through them | F7: Global only
A8: UAE | B8: Jailbird | C8: — | D8: — | E8: No ranking website — Instagram, Zomato, Talabat | F8: No
A9: UAE | B9: Fowli | C9: — | D9: — | E9: No ranking website — Facebook, Zomato, Instagram | F9: No
A10: UAE | B10: Peppers | C10: — | D10: — | E10: No ranking website | F10: No
A11: UAE | B11: Toit | C11: — | D11: — | E11: No ranking website — Instagram, Zomato, Talabat | F11: No
A12: UAE | B12: Crispy Chicken UAE (found) | C12: crispychicken-uae.com | D12: — | E12: Owns the 33,100/mo 'crispy chicken' brand search | F12: Yes
A13: UAE | B13: Bonbird | C13: bonbirdchicken.com | D13: 148 | E13: Top restaurant site for most generic local searches (#2–#5) | F13: Yes
A14: Pakistan | B14: KFC | C14: kfcpakistan.com | D14: 1000 | E14: Deals and prices ('zinger burger price', 'food deals') | F14: Yes
A15: Pakistan | B15: Kababjees Fried Chicken | C15: kababjeesfriedchicken.com | D15: 249 | E15: National SEO leader: #1 'fried chicken', 'fried chicken near me'; deal landing pages + blog | F15: Yes
A16: Pakistan | B16: Hen n Bun | C16: hennbun.pk | D16: 25 | E16: Mostly brand | F16: Yes
A17: Pakistan | B17: CP Five Star | C17: cpfivestar.pk | D17: 2 | E17: Negligible | F17: Yes
A18: Pakistan | B18: Mary Brown's | C18: marybrowns.com (global) | D18: 5 | E18: Negligible in Pakistan | F18: Global only
A19: Pakistan | B19: Fri-Chiks | C19: — | D19: — | E19: No ranking website — Facebook, TripAdvisor, foodpanda | F19: No
A20: Pakistan | B20: Bonbird | C20: bonbirdchicken.com | D20: 23 | E20: Ranks for its own brand + Lahore venues | F20: Yes
A21: Oman | B21: Fry Chicks, Fried Bowl, MFC (Muscat Fried Chicken), Cluck, El Baraka, CFC, Golden Crispy, Chikarro, Frispy (found) | C21: — | D21: — | E21: Compete on Maps, Talabat, Instagram — no ranking websites | F21: No
A22: Oman | B22: Bonbird | C22: bonbirdchicken.com | D22: — | E22: #1 organic for 'fried chicken muscat' and 'best fried chicken in oman' (live check) | F22: Yes
A23: Qatar | B23: Raising Cane's (found) | C23: — | D23: — | E23: Owns the Maps pack for 'fried chicken near me', 'best fried chicken in qatar', 'chicken restaurant doha' | F23: Maps
A24: Qatar | B24: Texas Chicken Qatar (found) | C24: qatar.texaschicken.com | D24: — | E24: #2 'best fried chicken in qatar' | F24: Yes
A25: Qatar | B25: Go Crispy (found) | C25: gocrispy.com | D25: — | E25: Maps pack 'fried chicken doha' | F25: Yes
A26: Qatar | B26: Hot Chicken (found) | C26: hotchicken.qa | D26: — | E26: Owns 'hot chicken' (brand) | F26: Yes
A27: Qatar | B27: Sultan Fried Chicken, Birdy's, Qokio, Drumsticks (found) | C27: — | D27: — | E27: Facebook / TripAdvisor / Snoonu | F27: No
A28: Qatar | B28: Bonbird | C28: bonbirdchicken.com | D28: — | E28: #2 'fried chicken doha', #6 'best fried chicken in qatar' (live check) | F28: Yes
A30: Oman and Qatar keyword counts are '—' because DataForSEO's ranked-keyword database does not cover those countries; competitors there were found from live Google results.

Sheet Excluded
A1: Market | B1: Keyword(s) | C1: Searches / mo | D1: Why we are not targeting it
A2: UAE | B2: crispy chicken | C2: 33100 | D2: Rival brand: 'Crispy Chicken UAE' (crispychicken-uae.com) ranks #1 with its Facebook, Zomato, 2GIS pages — people are looking for that restaurant
A3: UAE / Oman / Qatar | B3: broasted chicken, بروستد, broasted chicken near me | C3: 3600 | D3: Not on the menu (Bonbird sells fried, not broasted)
A4: UAE | B4: chicken wings / chicken nuggets | C4: 2900 | D4: Not on the menu
A5: Qatar | B5: hot chicken / hot chicken doha | C5: 1600 | D5: Rival brand 'Hot Chicken' (hotchicken.qa) dominates
A6: Oman | B6: hot chicken | C6: 880 | D6: Rival brand 'Hot Chicken' (@hotchicken.om) dominates
A7: Qatar | B7: restaurants in doha / best restaurants in doha | C7: 8100 | D7: Travel and luxury guides (OpenTable, Raffles, Condé Nast) — not winnable for a fried chicken venue
A8: Oman | B8: restaurants in muscat / best restaurants in muscat | C8: 4400 | D8: Travel guides (Independent, Time Out, Klook)
A9: Oman | B9: mall of oman restaurants | C9: 880 | D9: No Bonbird venue at Mall of Oman; mall's own site ranks
A10: Oman | B10: souq al madina | C10: 9900 | D10: Navigational — people looking for the mall itself
A11: Pakistan | B11: cue cinema lahore | C11: 8100 | D11: Navigational — people looking for the cinema; use as landmark in the Gulberg title only
A12: Pakistan | B12: packages mall food court / emporium mall food court | C12: 720 | D12: No Bonbird venue there
A13: UAE | B13: ibn battuta mall food court / al hamra mall restaurants | C13: 880 | D13: KFC ranks via store pages; no Bonbird venue there
A14: UAE | B14: drive thru near me (+ variants) | C14: 8100 | D14: KFC's territory; only relevant if Bonbird venues have a drive-thru
A15: All | B15: Competitor brand searches (KFC, Popeyes, Jollibee, Texas, Dave's, Kababjees…) | C15: — | D15: Navigational — 753 of 1,114 UAE competitor keywords were brand searches
A16: All | B16: Recipe searches (recipe, how to, calories…) | C16: — | D16: Cooks, not customers

Sheet Method & sources
A1: Method
A2: 1. Business: menu (fried chicken, Nashville hot style, 6 flavours: Plain, Medium, XXX Hot, Lemon Pepper, Chicken Salt, Jalapeño; no wings, nuggets or broasted), 12 venues in 4 markets.
A3: 2. Competitors: from Shazin (UAE, Pakistan) and live Google results (Oman, Qatar). Official domains confirmed by searching each brand name in its market.
A4: 3. Competitor keywords: DataForSEO Labs ranked_keywords for each competitor website (UAE, Pakistan). 1,114 UAE and 1,286 Pakistan keywords pulled, then cleaned: brand searches, recipes, off-menu items and other restaurants' names removed.
A5: 4. Volumes: Google Ads search volume via DataForSEO (monthly, country level). Where Google Ads reports no volume, Search Console impressions over 90 days are shown and labelled.
A6: 5. Winnability: live Google page one (mobile, country level) for the biggest clusters via DataForSEO standard SERP queue.
A7: 6. Bonbird positions: 'snapshot' = DataForSEO Labs position at its sampled location; 'GSC avg' = Search Console average position (all users, 90 days); 'live' = the page-one check above.
A8: Limitations
A9: • Keyword difficulty (KD) is mostly unavailable for these markets — DataForSEO returns 0 or nothing for UAE/PK/OM/QA local terms. Winnability was judged from page one instead.
A10: • DataForSEO's ranked-keyword database does not cover Oman or Qatar; those lists come from Google Ads volumes + Search Console + live results.
A11: • Google Ads rounds and groups close variants (e.g. 'best fried chicken dubai' and '… in dubai' share 590).
A12: • Page-one checks were country level; a phone in a specific city can see a different Maps pack.
... A15: DataForSEO Labs ranked_keywords/live, keyword search volume (Google Ads), SERP organic task_post/task_get (advanced) — via the Nest /api/keyword-metrics (v7.9.123–127). Google Search Console via /api/market-traffic (queries mode), 8 Jul – 6 Oct 2026.
